Workbook

Sheet Sheet1
C1: Not at all | D1: 1 to 5 times | E1: 6 to 5 times | F1: 11 to 20 times | G1: 21 to 50 times | H1: More than 50 times
B2: Sample | C2: =_xlfn.CONCAT(Sheet2!E11," (",ROUND(Sheet2!E12,2),"%)") -> 95 (1.4%) | D2: =_xlfn.CONCAT(Sheet2!F11," (",ROUND(Sheet2!F12,2),"%)") -> 1768 (26%) | E2: =_xlfn.CONCAT(Sheet2!G11," (",ROUND(Sheet2!G12,2),"%)") -> 1945 (28.6%) | F2: =_xlfn.CONCAT(Sheet2!H11," (",ROUND(Sheet2!H12,2),"%)") -> 1876 (27.59%) | G2: =_xlfn.CONCAT(Sheet2!I11," (",ROUND(Sheet2!I12,2),"%)") -> 1007 (14.81%) | H2: =_xlfn.CONCAT(Sheet2!J11," (",ROUND(Sheet2!J12,2),"%)") -> 109 (1.6%) | I2: =SUM(Sheet2!E11:J11) -> 6800
B3: Couple Agreement | C3: =_xlfn.CONCAT(Sheet2!E13," (",ROUND(Sheet2!E19,2),"%)") -> 6 (0.31%) | D3: =_xlfn.CONCAT(Sheet2!F13," (",ROUND(Sheet2!F19,2),"%)") -> 167 (8.69%) | E3: =_xlfn.CONCAT(Sheet2!G13," (",ROUND(Sheet2!G19,2),"%)") -> 382 (19.89%) | F3: =_xlfn.CONCAT(Sheet2!H13," (",ROUND(Sheet2!H19,2),"%)") -> 676 (35.19%) | G3: =_xlfn.CONCAT(Sheet2!I13," (",ROUND(Sheet2!I19,2),"%)") -> 589 (30.66%) | H3: =_xlfn.CONCAT(Sheet2!J13," (",ROUND(Sheet2!J19,2),"%)") -> 101 (5.26%) | I3: =SUM(Sheet2!E13:J13) -> 1921 | J3: =I3*100/$I$2 -> 28.25
B4: One-sided Deprivation | C4: =_xlfn.CONCAT(Sheet2!E14," (",ROUND(Sheet2!E20,2),"%)") -> 35 (1.42%) | D4: =_xlfn.CONCAT(Sheet2!F14," (",ROUND(Sheet2!F20,2),"%)") -> 640 (25.91%) | E4: =_xlfn.CONCAT(Sheet2!G14," (",ROUND(Sheet2!G20,2),"%)") -> 825 (33.4%) | F4: =_xlfn.CONCAT(Sheet2!H14," (",ROUND(Sheet2!H20,2),"%)") -> 731 (29.6%) | G4: =_xlfn.CONCAT(Sheet2!I14," (",ROUND(Sheet2!I20,2),"%)") -> 239 (9.68%) | H4: =_xlfn.CONCAT(Sheet2!J14," (",ROUND(Sheet2!J20,2),"%)") -> 0 (0%) | I4: =SUM(Sheet2!E14:J14) -> 2470 | J4: =I4*100/$I$2 -> 36.323529
B5: One-sided Saturation | C5: =_xlfn.CONCAT(Sheet2!E15," (",ROUND(Sheet2!E21,2),"%)") -> 2 (0.6%) | D5: =_xlfn.CONCAT(Sheet2!F15," (",ROUND(Sheet2!F21,2),"%)") -> 29 (8.71%) | E5: =_xlfn.CONCAT(Sheet2!G15," (",ROUND(Sheet2!G21,2),"%)") -> 59 (17.72%) | F5: =_xlfn.CONCAT(Sheet2!H15," (",ROUND(Sheet2!H21,2),"%)") -> 139 (41.74%) | G5: =_xlfn.CONCAT(Sheet2!I15," (",ROUND(Sheet2!I21,2),"%)") -> 98 (29.43%) | H5: =_xlfn.CONCAT(Sheet2!J15," (",ROUND(Sheet2!J21,2),"%)") -> 6 (1.8%) | I5: =SUM(Sheet2!E15:J15) -> 333 | J5: =I5*100/$I$2 -> 4.8970588
B6: Couple Deprivation | C6: =_xlfn.CONCAT(Sheet2!E16," (",ROUND(Sheet2!E22,2),"%)") -> 46 (2.7%) | D6: =_xlfn.CONCAT(Sheet2!F16," (",ROUND(Sheet2!F22,2),"%)") -> 840 (49.38%) | E6: =_xlfn.CONCAT(Sheet2!G16," (",ROUND(Sheet2!G22,2),"%)") -> 536 (31.51%) | F6: =_xlfn.CONCAT(Sheet2!H16," (",ROUND(Sheet2!H22,2),"%)") -> 242 (14.23%) | G6: =_xlfn.CONCAT(Sheet2!I16," (",ROUND(Sheet2!I22,2),"%)") -> 37 (2.18%) | H6: =_xlfn.CONCAT(Sheet2!J16," (",ROUND(Sheet2!J22,2),"%)") -> 0 (0%) | I6: =SUM(Sheet2!E16:J16) -> 1701 | J6: =I6*100/$I$2 -> 25.014706
B7: Couple Saturation | C7: =_xlfn.CONCAT(Sheet2!E17," (",ROUND(Sheet2!E23,2),"%)") -> 0 (0%) | D7: =_xlfn.CONCAT(Sheet2!F17," (",ROUND(Sheet2!F23,2),"%)") -> 3 (6.67%) | E7: =_xlfn.CONCAT(Sheet2!G17," (",ROUND(Sheet2!G23,2),"%)") -> 11 (24.44%) | F7: =_xlfn.CONCAT(Sheet2!H17," (",ROUND(Sheet2!H23,2),"%)") -> 15 (33.33%) | G7: =_xlfn.CONCAT(Sheet2!I17," (",ROUND(Sheet2!I23,2),"%)") -> 14 (31.11%) | H7: =_xlfn.CONCAT(Sheet2!J17," (",ROUND(Sheet2!J23,2),"%)") -> 2 (4.44%) | I7: =SUM(Sheet2!E17:J17) -> 45 | J7: =I7*100/$I$2 -> 0.66176471
B8: Couple Disagreement | C8: =_xlfn.CONCAT(Sheet2!E18," (",ROUND(Sheet2!E24,2),"%)") -> 6 (1.82%) | D8: =_xlfn.CONCAT(Sheet2!F18," (",ROUND(Sheet2!F24,2),"%)") -> 89 (26.97%) | E8: =_xlfn.CONCAT(Sheet2!G18," (",ROUND(Sheet2!G24,2),"%)") -> 132 (40%) | F8: =_xlfn.CONCAT(Sheet2!H18," (",ROUND(Sheet2!H24,2),"%)") -> 73 (22.12%) | G8: =_xlfn.CONCAT(Sheet2!I18," (",ROUND(Sheet2!I24,2),"%)") -> 30 (9.09%) | H8: =_xlfn.CONCAT(Sheet2!J18," (",ROUND(Sheet2!J24,2),"%)") -> 0 (0%) | I8: =SUM(Sheet2!E18:J18) -> 330 | J8: =I8*100/$I$2 -> 4.8529412
C10: mean | D10: sd | E10: median
B11: Couple Agreement | C11: 0 | D11: 0 | E11: 0
B12: One-sided Deprivation | C12: 0.46902834 | D12: 0.71260299 | E12: 0.16666667
B13: One-sided Saturation | C13: -0.52552553 | D13: 0.95623484 | E13: -0.16666667
B14: Couple Deprivation | C14: 1.0571233 | D14: 0.80515612 | E14: 1
B15: Couple Saturation | C15: -1.5888889 | D15: 1.3519764 | E15: -1.3333333
B16: Couple Disagreement | C16: 0.044444444 | D16: 1.2520943 | E16: 0
C19: Not at all | D19: 1 to 5 times | E19: 6 to 5 times | F19: 11 to 20 times | G19: 21 to 50 times | H19: More than 50 times | I19: Total
B20: Sample | C20: =_xlfn.CONCAT(Sheet2!P10," (",ROUND(Sheet2!P11,2),"%)") -> 457 (3.36%) | D20: =_xlfn.CONCAT(Sheet2!Q10," (",ROUND(Sheet2!Q11,2),"%)") -> 3444 (25.32%) | E20: =_xlfn.CONCAT(Sheet2!R10," (",ROUND(Sheet2!R11,2),"%)") -> 3277 (24.1%) | F20: =_xlfn.CONCAT(Sheet2!S10," (",ROUND(Sheet2!S11,2),"%)") -> 3332 (24.5%) | G20: =_xlfn.CONCAT(Sheet2!T10," (",ROUND(Sheet2!T11,2),"%)") -> 2325 (17.1%) | H20: =_xlfn.CONCAT(Sheet2!U10," (",ROUND(Sheet2!U11,2),"%)") -> 765 (5.63%)
B21: SubGroup1 | C21: =_xlfn.CONCAT(Sheet2!P12," (",ROUND(Sheet2!P21,2),"%)") -> 23 (0.6%) | D21: =_xlfn.CONCAT(Sheet2!Q12," (",ROUND(Sheet2!Q21,2),"%)") -> 386 (10.05%) | E21: =_xlfn.CONCAT(Sheet2!R12," (",ROUND(Sheet2!R21,2),"%)") -> 698 (18.17%) | F21: =_xlfn.CONCAT(Sheet2!S12," (",ROUND(Sheet2!S21,2),"%)") -> 1104 (28.74%) | G21: =_xlfn.CONCAT(Sheet2!T12," (",ROUND(Sheet2!T21,2),"%)") -> 1100 (28.63%) | H21: =_xlfn.CONCAT(Sheet2!U12," (",ROUND(Sheet2!U21,2),"%)") -> 531 (13.82%)
B22: SubGroup2 | C22: =_xlfn.CONCAT(Sheet2!P13," (",ROUND(Sheet2!P22,2),"%)") -> 81 (3.89%) | D22: =_xlfn.CONCAT(Sheet2!Q13," (",ROUND(Sheet2!Q22,2),"%)") -> 549 (26.34%) | E22: =_xlfn.CONCAT(Sheet2!R13," (",ROUND(Sheet2!R22,2),"%)") -> 531 (25.48%) | F22: =_xlfn.CONCAT(Sheet2!S13," (",ROUND(Sheet2!S22,2),"%)") -> 570 (27.35%) | G22: =_xlfn.CONCAT(Sheet2!T13," (",ROUND(Sheet2!T22,2),"%)") -> 296 (14.2%) | H22: =_xlfn.CONCAT(Sheet2!U13," (",ROUND(Sheet2!U22,2),"%)") -> 57 (2.74%)
B23: SubGroup3 | C23: =_xlfn.CONCAT(Sheet2!P14," (",ROUND(Sheet2!P23,2),"%)") -> 224 (6.58%) | D23: =_xlfn.CONCAT(Sheet2!Q14," (",ROUND(Sheet2!Q23,2),"%)") -> 1471 (43.24%) | E23: =_xlfn.CONCAT(Sheet2!R14," (",ROUND(Sheet2!R23,2),"%)") -> 955 (28.07%) | F23: =_xlfn.CONCAT(Sheet2!S14," (",ROUND(Sheet2!S23,2),"%)") -> 576 (16.93%) | G23: =_xlfn.CONCAT(Sheet2!T14," (",ROUND(Sheet2!T23,2),"%)") -> 176 (5.17%) | H23: =_xlfn.CONCAT(Sheet2!U14," (",ROUND(Sheet2!U23,2),"%)") -> 0 (0%)
B24: SubGroup4 | C24: =_xlfn.CONCAT(Sheet2!P15," (",ROUND(Sheet2!P24,2),"%)") -> 9 (3.08%) | D24: =_xlfn.CONCAT(Sheet2!Q15," (",ROUND(Sheet2!Q24,2),"%)") -> 87 (29.79%) | E24: =_xlfn.CONCAT(Sheet2!R15," (",ROUND(Sheet2!R24,2),"%)") -> 83 (28.42%) | F24: =_xlfn.CONCAT(Sheet2!S15," (",ROUND(Sheet2!S24,2),"%)") -> 72 (24.66%) | G24: =_xlfn.CONCAT(Sheet2!T15," (",ROUND(Sheet2!T24,2),"%)") -> 35 (11.99%) | H24: =_xlfn.CONCAT(Sheet2!U15," (",ROUND(Sheet2!U24,2),"%)") -> 6 (2.05%)
B25: SubGroup5 | C25: =_xlfn.CONCAT(Sheet2!P16," (",ROUND(Sheet2!P25,2),"%)") -> 3 (1.06%) | D25: =_xlfn.CONCAT(Sheet2!Q16," (",ROUND(Sheet2!Q25,2),"%)") -> 39 (13.73%) | E25: =_xlfn.CONCAT(Sheet2!R16," (",ROUND(Sheet2!R25,2),"%)") -> 54 (19.01%) | F25: =_xlfn.CONCAT(Sheet2!S16," (",ROUND(Sheet2!S25,2),"%)") -> 84 (29.58%) | G25: =_xlfn.CONCAT(Sheet2!T16," (",ROUND(Sheet2!T25,2),"%)") -> 72 (25.35%) | H25: =_xlfn.CONCAT(Sheet2!U16," (",ROUND(Sheet2!U25,2),"%)") -> 32 (11.27%)
B26: SubGroup6 | C26: =_xlfn.CONCAT(Sheet2!P17," (",ROUND(Sheet2!P26,2),"%)") -> 0 (0%) | D26: =_xlfn.CONCAT(Sheet2!Q17," (",ROUND(Sheet2!Q26,2),"%)") -> 10 (11.11%) | E26: =_xlfn.CONCAT(Sheet2!R17," (",ROUND(Sheet2!R26,2),"%)") -> 17 (18.89%) | F26: =_xlfn.CONCAT(Sheet2!S17," (",ROUND(Sheet2!S26,2),"%)") -> 28 (31.11%) | G26: =_xlfn.CONCAT(Sheet2!T17," (",ROUND(Sheet2!T26,2),"%)") -> 24 (26.67%) | H26: =_xlfn.CONCAT(Sheet2!U17," (",ROUND(Sheet2!U26,2),"%)") -> 11 (12.22%)
B27: SubGroup7 | C27: =_xlfn.CONCAT(Sheet2!P18," (",ROUND(Sheet2!P27,2),"%)") -> 100 (3.5%) | D27: =_xlfn.CONCAT(Sheet2!Q18," (",ROUND(Sheet2!Q27,2),"%)") -> 765 (26.79%) | E27: =_xlfn.CONCAT(Sheet2!R18," (",ROUND(Sheet2!R27,2),"%)") -> 770 (26.96%) | F27: =_xlfn.CONCAT(Sheet2!S18," (",ROUND(Sheet2!S27,2),"%)") -> 682 (23.88%) | G27: =_xlfn.CONCAT(Sheet2!T18," (",ROUND(Sheet2!T27,2),"%)") -> 457 (16%) | H27: =_xlfn.CONCAT(Sheet2!U18," (",ROUND(Sheet2!U27,2),"%)") -> 82 (2.87%)
B28: SubGroup8 | C28: =_xlfn.CONCAT(Sheet2!P19," (",ROUND(Sheet2!P28,2),"%)") -> 2 (0.52%) | D28: =_xlfn.CONCAT(Sheet2!Q19," (",ROUND(Sheet2!Q28,2),"%)") -> 33 (8.64%) | E28: =_xlfn.CONCAT(Sheet2!R19," (",ROUND(Sheet2!R28,2),"%)") -> 60 (15.71%) | F28: =_xlfn.CONCAT(Sheet2!S19," (",ROUND(Sheet2!S28,2),"%)") -> 132 (34.55%) | G28: =_xlfn.CONCAT(Sheet2!T19," (",ROUND(Sheet2!T28,2),"%)") -> 116 (30.37%) | H28: =_xlfn.CONCAT(Sheet2!U19," (",ROUND(Sheet2!U28,2),"%)") -> 39 (10.21%)
B29: SubGroup9 | C29: =_xlfn.CONCAT(Sheet2!P20," (",ROUND(Sheet2!P29,2),"%)") -> 15 (4.08%) | D29: =_xlfn.CONCAT(Sheet2!Q20," (",ROUND(Sheet2!Q29,2),"%)") -> 104 (28.26%) | E29: =_xlfn.CONCAT(Sheet2!R20," (",ROUND(Sheet2!R29,2),"%)") -> 109 (29.62%) | F29: =_xlfn.CONCAT(Sheet2!S20," (",ROUND(Sheet2!S29,2),"%)") -> 84 (22.83%) | G29: =_xlfn.CONCAT(Sheet2!T20," (",ROUND(Sheet2!T29,2),"%)") -> 49 (13.32%) | H29: =_xlfn.CONCAT(Sheet2!U20," (",ROUND(Sheet2!U29,2),"%)") -> 7 (1.9%)
C31: Not at all | D31: 1 to 5 times | E31: 6 to 5 times | F31: 11 to 20 times | G31: 21 to 50 times | H31: More than 50 times
B32: =_xlfn.CONCAT("Whole Sample"," (n = ",Sheet2!K11,")") -> Whole Sample (n = 6800) | C32: =_xlfn.CONCAT(Sheet2!E11," (",ROUND(Sheet2!E12,2),"%)") -> 95 (1.4%) | D32: =_xlfn.CONCAT(Sheet2!F11," (",ROUND(Sheet2!F12,2),"%)") -> 1768 (26%) | E32: =_xlfn.CONCAT(Sheet2!G11," (",ROUND(Sheet2!G12,2),"%)") -> 1945 (28.6%) | F32: =_xlfn.CONCAT(Sheet2!H11," (",ROUND(Sheet2!H12,2),"%)") -> 1876 (27.59%) | G32: =_xlfn.CONCAT(Sheet2!I11," (",ROUND(Sheet2!I12,2),"%)") -> 1007 (14.81%) | H32: =_xlfn.CONCAT(Sheet2!J11," (",ROUND(Sheet2!J12,2),"%)") -> 109 (1.6%)
B33: =_xlfn.CONCAT("Satisfied"," (n = ",Sheet2!K13,")") -> Satisfied (n = 1921) | C33: =_xlfn.CONCAT(Sheet2!E13," (",ROUND(Sheet2!E19,2),"%)") -> 6 (0.31%) | D33: =_xlfn.CONCAT(Sheet2!F13," (",ROUND(Sheet2!F19,2),"%)") -> 167 (8.69%) | E33: =_xlfn.CONCAT(Sheet2!G13," (",ROUND(Sheet2!G19,2),"%)") -> 382 (19.89%) | F33: =_xlfn.CONCAT(Sheet2!H13," (",ROUND(Sheet2!H19,2),"%)") -> 676 (35.19%) | G33: =_xlfn.CONCAT(Sheet2!I13," (",ROUND(Sheet2!I19,2),"%)") -> 589 (30.66%) | H33: =_xlfn.CONCAT(Sheet2!J13," (",ROUND(Sheet2!J19,2),"%)") -> 101 (5.26%)
B34: =_xlfn.CONCAT("Deprived: both partners"," (n = ",Sheet2!K16,")") -> Deprived: both partners (n = 1701) | C34: =_xlfn.CONCAT(Sheet2!E16," (",ROUND(Sheet2!E22,2),"%)") -> 46 (2.7%) | D34: =_xlfn.CONCAT(Sheet2!F16," (",ROUND(Sheet2!F22,2),"%)") -> 840 (49.38%) | E34: =_xlfn.CONCAT(Sheet2!G16," (",ROUND(Sheet2!G22,2),"%)") -> 536 (31.51%) | F34: =_xlfn.CONCAT(Sheet2!H16," (",ROUND(Sheet2!H22,2),"%)") -> 242 (14.23%) | G34: =_xlfn.CONCAT(Sheet2!I16," (",ROUND(Sheet2!I22,2),"%)") -> 37 (2.18%) | H34: =_xlfn.CONCAT(Sheet2!J16," (",ROUND(Sheet2!J22,2),"%)") -> 0 (0%)
B35: =_xlfn.CONCAT("Deprived: one partner"," (n = ",Sheet2!K14,")") -> Deprived: one partner (n = 2470) | C35: =_xlfn.CONCAT(Sheet2!E14," (",ROUND(Sheet2!E20,2),"%)") -> 35 (1.42%) | D35: =_xlfn.CONCAT(Sheet2!F14," (",ROUND(Sheet2!F20,2),"%)") -> 640 (25.91%) | E35: =_xlfn.CONCAT(Sheet2!G14," (",ROUND(Sheet2!G20,2),"%)") -> 825 (33.4%) | F35: =_xlfn.CONCAT(Sheet2!H14," (",ROUND(Sheet2!H20,2),"%)") -> 731 (29.6%) | G35: =_xlfn.CONCAT(Sheet2!I14," (",ROUND(Sheet2!I20,2),"%)") -> 239 (9.68%) | H35: =_xlfn.CONCAT(Sheet2!J14," (",ROUND(Sheet2!J20,2),"%)") -> 0 (0%)
B36: =_xlfn.CONCAT("Deprived: me"," (n = ",Sheet2!V34,")") -> Deprived: me (n = 1042) | C36: =_xlfn.CONCAT(Sheet2!P34," (",ROUND(Sheet2!P43,2),"%)") -> 41 (3.93%) | D36: =_xlfn.CONCAT(Sheet2!Q34," (",ROUND(Sheet2!Q43,2),"%)") -> 274 (26.3%) | E36: =_xlfn.CONCAT(Sheet2!R34," (",ROUND(Sheet2!R43,2),"%)") -> 266 (25.53%) | F36: =_xlfn.CONCAT(Sheet2!S34," (",ROUND(Sheet2!S43,2),"%)") -> 285 (27.35%) | G36: =_xlfn.CONCAT(Sheet2!T34," (",ROUND(Sheet2!T43,2),"%)") -> 148 (14.2%) | H36: =_xlfn.CONCAT(Sheet2!U34," (",ROUND(Sheet2!U43,2),"%)") -> 28 (2.69%)
B37: =_xlfn.CONCAT("Deprived: partner"," (n = ",Sheet2!V39,")") -> Deprived: partner (n = 1428) | C37: =_xlfn.CONCAT(Sheet2!P39," (",ROUND(Sheet2!P48,2),"%)") -> 50 (3.5%) | D37: =_xlfn.CONCAT(Sheet2!Q39," (",ROUND(Sheet2!Q48,2),"%)") -> 382 (26.75%) | E37: =_xlfn.CONCAT(Sheet2!R39," (",ROUND(Sheet2!R48,2),"%)") -> 385 (26.96%) | F37: =_xlfn.CONCAT(Sheet2!S39," (",ROUND(Sheet2!S48,2),"%)") -> 341 (23.88%) | G37: =_xlfn.CONCAT(Sheet2!T39," (",ROUND(Sheet2!T48,2),"%)") -> 229 (16.04%) | H37: =_xlfn.CONCAT(Sheet2!U39," (",ROUND(Sheet2!U48,2),"%)") -> 41 (2.87%)
B38: =_xlfn.CONCAT("Saturated: both partners"," (n = ",Sheet2!V38,")") -> Saturated: both partners (n = 45) | C38: =_xlfn.CONCAT(Sheet2!E17," (",ROUND(Sheet2!P47,2),"%)") -> 0 (0%) | D38: =_xlfn.CONCAT(Sheet2!F17," (",ROUND(Sheet2!Q47,2),"%)") -> 3 (11.11%) | E38: =_xlfn.CONCAT(Sheet2!G17," (",ROUND(Sheet2!R47,2),"%)") -> 11 (20%) | F38: =_xlfn.CONCAT(Sheet2!H17," (",ROUND(Sheet2!S47,2),"%)") -> 15 (31.11%) | G38: =_xlfn.CONCAT(Sheet2!I17," (",ROUND(Sheet2!T47,2),"%)") -> 14 (26.67%) | H38: =_xlfn.CONCAT(Sheet2!J17," (",ROUND(Sheet2!U47,2),"%)") -> 2 (11.11%)
B39: =_xlfn.CONCAT("Saturated: One Partner"," (n = ",Sheet2!K15,")") -> Saturated: One Partner (n = 333) | C39: =_xlfn.CONCAT(Sheet2!E15," (",ROUND(Sheet2!E21,2),"%)") -> 2 (0.6%) | D39: =_xlfn.CONCAT(Sheet2!F15," (",ROUND(Sheet2!F21,2),"%)") -> 29 (8.71%) | E39: =_xlfn.CONCAT(Sheet2!G15," (",ROUND(Sheet2!G21,2),"%)") -> 59 (17.72%) | F39: =_xlfn.CONCAT(Sheet2!H15," (",ROUND(Sheet2!H21,2),"%)") -> 139 (41.74%) | G39: =_xlfn.CONCAT(Sheet2!I15," (",ROUND(Sheet2!I21,2),"%)") -> 98 (29.43%) | H39: =_xlfn.CONCAT(Sheet2!J15," (",ROUND(Sheet2!J21,2),"%)") -> 6 (1.8%)
B40: =_xlfn.CONCAT("Saturated: me"," (n = ",Sheet2!V37,")") -> Saturated: me (n = 142) | C40: =_xlfn.CONCAT(Sheet2!P37," (",ROUND(Sheet2!P46,2),"%)") -> 2 (1.41%) | D40: =_xlfn.CONCAT(Sheet2!Q37," (",ROUND(Sheet2!Q46,2),"%)") -> 19 (13.38%) | E40: =_xlfn.CONCAT(Sheet2!R37," (",ROUND(Sheet2!R46,2),"%)") -> 27 (19.01%) | F40: =_xlfn.CONCAT(Sheet2!S37," (",ROUND(Sheet2!S46,2),"%)") -> 42 (29.58%) | G40: =_xlfn.CONCAT(Sheet2!T37," (",ROUND(Sheet2!T46,2),"%)") -> 36 (25.35%) | H40: =_xlfn.CONCAT(Sheet2!U37," (",ROUND(Sheet2!U46,2),"%)") -> 16 (11.27%)
B41: =_xlfn.CONCAT("Saturated: partner"," (n = ",Sheet2!V40,")") -> Saturated: partner (n = 191) | C41: =_xlfn.CONCAT(Sheet2!P40," (",ROUND(Sheet2!P49,2),"%)") -> 1 (0.52%) | D41: =_xlfn.CONCAT(Sheet2!Q40," (",ROUND(Sheet2!Q49,2),"%)") -> 17 (8.9%) | E41: =_xlfn.CONCAT(Sheet2!R40," (",ROUND(Sheet2!R49,2),"%)") -> 30 (15.71%) | F41: =_xlfn.CONCAT(Sheet2!S40," (",ROUND(Sheet2!S49,2),"%)") -> 66 (34.55%) | G41: =_xlfn.CONCAT(Sheet2!T40," (",ROUND(Sheet2!T49,2),"%)") -> 58 (30.37%) | H41: =_xlfn.CONCAT(Sheet2!U40," (",ROUND(Sheet2!U49,2),"%)") -> 19 (9.95%)
B42: =_xlfn.CONCAT("Mixed: one deprived, one saturated"," (n = ",Sheet2!K18,")") -> Mixed: one deprived, one saturated (n = 330) | C42: =_xlfn.CONCAT(Sheet2!E18," (",ROUND(Sheet2!E24,2),"%)") -> 6 (1.82%) | D42: =_xlfn.CONCAT(Sheet2!F18," (",ROUND(Sheet2!F24,2),"%)") -> 89 (26.97%) | E42: =_xlfn.CONCAT(Sheet2!G18," (",ROUND(Sheet2!G24,2),"%)") -> 132 (40%) | F42: =_xlfn.CONCAT(Sheet2!H18," (",ROUND(Sheet2!H24,2),"%)") -> 73 (22.12%) | G42: =_xlfn.CONCAT(Sheet2!I18," (",ROUND(Sheet2!I24,2),"%)") -> 30 (9.09%) | H42: =_xlfn.CONCAT(Sheet2!J18," (",ROUND(Sheet2!J24,2),"%)") -> 0 (0%)
B43: =_xlfn.CONCAT("Me deprived, partner saturated"," (n = ",Sheet2!V36,")") -> Me deprived, partner saturated (n = 146) | C43: =_xlfn.CONCAT(Sheet2!P36," (",ROUND(Sheet2!P45,2),"%)") -> 5 (3.42%) | D43: =_xlfn.CONCAT(Sheet2!Q36," (",ROUND(Sheet2!Q45,2),"%)") -> 43 (29.45%) | E43: =_xlfn.CONCAT(Sheet2!R36," (",ROUND(Sheet2!R45,2),"%)") -> 41 (28.08%) | F43: =_xlfn.CONCAT(Sheet2!S36," (",ROUND(Sheet2!S45,2),"%)") -> 36 (24.66%) | G43: =_xlfn.CONCAT(Sheet2!T36," (",ROUND(Sheet2!T45,2),"%)") -> 18 (12.33%) | H43: =_xlfn.CONCAT(Sheet2!U36," (",ROUND(Sheet2!U45,2),"%)") -> 3 (2.05%)
B44: =_xlfn.CONCAT("Me saturated, partner deprived"," (n = ",Sheet2!V41,")") -> Me saturated, partner deprived (n = 184) | C44: =_xlfn.CONCAT(Sheet2!P41," (",ROUND(Sheet2!P50,2),"%)") -> 8 (4.35%) | D44: =_xlfn.CONCAT(Sheet2!Q41," (",ROUND(Sheet2!Q50,2),"%)") -> 52 (28.26%) | E44: =_xlfn.CONCAT(Sheet2!R41," (",ROUND(Sheet2!R50,2),"%)") -> 55 (29.89%) | F44: =_xlfn.CONCAT(Sheet2!S41," (",ROUND(Sheet2!S50,2),"%)") -> 42 (22.83%) | G44: =_xlfn.CONCAT(Sheet2!T41," (",ROUND(Sheet2!T50,2),"%)") -> 24 (13.04%) | H44: =_xlfn.CONCAT(Sheet2!U41," (",ROUND(Sheet2!U50,2),"%)") -> 3 (1.63%)

Sheet Sheet2
P9: 0 | Q9: 1 | R9: 2 | S9: 3 | T9: 4 | U9: 5
E10: 0 | F10: 1 | G10: 2 | H10: 3 | I10: 4 | J10: 5 | P10: 457 | Q10: 3444 | R10: 3277 | S10: 3332 | T10: 2325 | U10: 765
D11: Whole | E11: 95 | F11: 1768 | G11: 1945 | H11: 1876 | I11: 1007 | J11: 109 | K11: =SUM(E11:J11) -> 6800 | P11: 3.3602941 | Q11: 25.323529 | R11: 24.095588 | S11: 24.5 | T11: 17.095588 | U11: 5.625
E12: 1.3970588 | F12: 26 | G12: 28.602941 | H12: 27.588235 | I12: 14.808824 | J12: 1.6029412 | O12: SubGroup1 | P12: 23 | Q12: 386 | R12: 698 | S12: 1104 | T12: 1100 | U12: 531 | V12: =SUM(P12:U12) -> 3842
D13: Couple Agreement | E13: 6 | F13: 167 | G13: 382 | H13: 676 | I13: 589 | J13: 101 | K13: =SUM(E13:J13) -> 1921 | O13: SubGroup2 | P13: 81 | Q13: 549 | R13: 531 | S13: 570 | T13: 296 | U13: 57 | V13: =SUM(P13:U13) -> 2084
D14: One-sided Deprivation | E14: 35 | F14: 640 | G14: 825 | H14: 731 | I14: 239 | J14: 0 | K14: =SUM(E14:J14) -> 2470 | O14: SubGroup3 | P14: 224 | Q14: 1471 | R14: 955 | S14: 576 | T14: 176 | U14: 0 | V14: =SUM(P14:U14) -> 3402
D15: One-sided Saturation | E15: 2 | F15: 29 | G15: 59 | H15: 139 | I15: 98 | J15: 6 | K15: =SUM(E15:J15) -> 333 | O15: SubGroup4 | P15: 9 | Q15: 87 | R15: 83 | S15: 72 | T15: 35 | U15: 6 | V15: =SUM(P15:U15) -> 292
B16: 6800 | D16: Couple Deprivation | E16: 46 | F16: 840 | G16: 536 | H16: 242 | I16: 37 | J16: 0 | K16: =SUM(E16:J16) -> 1701 | M16: =B16*2 -> 13600 | O16: SubGroup5 | P16: 3 | Q16: 39 | R16: 54 | S16: 84 | T16: 72 | U16: 32 | V16: =SUM(P16:U16) -> 284
D17: Couple Saturation | E17: 0 | F17: 3 | G17: 11 | H17: 15 | I17: 14 | J17: 2 | K17: =SUM(E17:J17) -> 45 | O17: SubGroup6 | P17: 0 | Q17: 10 | R17: 17 | S17: 28 | T17: 24 | U17: 11 | V17: =SUM(P17:U17) -> 90
D18: Couple Disagreement | E18: 6 | F18: 89 | G18: 132 | H18: 73 | I18: 30 | J18: 0 | K18: =SUM(E18:J18) -> 330 | O18: SubGroup7 | P18: 100 | Q18: 765 | R18: 770 | S18: 682 | T18: 457 | U18: 82 | V18: =SUM(P18:U18) -> 2856
D19: Couple Agreement | E19: =E13*100/$K$13 -> 0.31233732 | F19: =F13*100/$K$13 -> 8.6933889 | G19: =G13*100/$K$13 -> 19.885476 | H19: =H13*100/$K$13 -> 35.190005 | I19: =I13*100/$K$13 -> 30.661114 | J19: =J13*100/$K$13 -> 5.2576783 | O19: SubGroup8 | P19: 2 | Q19: 33 | R19: 60 | S19: 132 | T19: 116 | U19: 39 | V19: =SUM(P19:U19) -> 382
D20: One-sided Deprivation | E20: =E14*100/$K$14 -> 1.417004 | F20: =F14*100/$K$14 -> 25.910931 | G20: =G14*100/$K$14 -> 33.40081 | H20: =H14*100/$K$14 -> 29.595142 | I20: =I14*100/$K$14 -> 9.6761134 | J20: =J14*100/$K$14 -> 0 | O20: SubGroup9 | P20: 15 | Q20: 104 | R20: 109 | S20: 84 | T20: 49 | U20: 7 | V20: =SUM(P20:U20) -> 368
D21: One-sided Saturation | E21: =E15*100/$K$15 -> 0.6006006 | F21: =F15*100/$K$15 -> 8.7087087 | G21: =G15*100/$K$15 -> 17.717718 | H21: =H15*100/$K$15 -> 41.741742 | I21: =I15*100/$K$15 -> 29.429429 | J21: =J15*100/$K$15 -> 1.8018018 | O21: SubGroup1 | P21: =P12*100/$V$12 -> 0.59864654 | Q21: =Q12*100/$V$12 -> 10.046851 | R21: =R12*100/$V$12 -> 18.167621 | S21: =S12*100/$V$12 -> 28.735034 | T21: =T12*100/$V$12 -> 28.630921 | U21: =U12*100/$V$12 -> 13.820927
D22: Couple Deprivation | E22: =E16*100/$K$16 -> 2.7042916 | F22: =F16*100/$K$16 -> 49.382716 | G22: =G16*100/$K$16 -> 31.510876 | H22: =H16*100/$K$16 -> 14.226925 | I22: =I16*100/$K$16 -> 2.1751911 | J22: =J16*100/$K$16 -> 0 | O22: SubGroup2 | P22: =P13*100/$V$13 -> 3.8867562 | Q22: =Q13*100/$V$13 -> 26.34357 | R22: =R13*100/$V$13 -> 25.479846 | S22: =S13*100/$V$13 -> 27.351248 | T22: =T13*100/$V$13 -> 14.203455 | U22: =U13*100/$V$13 -> 2.7351248
D23: Couple Saturation | E23: =E17*100/$K$17 -> 0 | F23: =F17*100/$K$17 -> 6.6666667 | G23: =G17*100/$K$17 -> 24.444444 | H23: =H17*100/$K$17 -> 33.333333 | I23: =I17*100/$K$17 -> 31.111111 | J23: =J17*100/$K$17 -> 4.4444444 | O23: SubGroup3 | P23: =P14*100/$V$14 -> 6.5843621 | Q23: =Q14*100/$V$14 -> 43.239271 | R23: =R14*100/$V$14 -> 28.071723 | S23: =S14*100/$V$14 -> 16.931217 | T23: =T14*100/$V$14 -> 5.1734274 | U23: =U14*100/$V$14 -> 0
D24: Couple Disagreement | E24: =E18*100/$K$18 -> 1.8181818 | F24: =F18*100/$K$18 -> 26.969697 | G24: =G18*100/$K$18 -> 40 | H24: =H18*100/$K$18 -> 22.121212 | I24: =I18*100/$K$18 -> 9.0909091 | J24: =J18*100/$K$18 -> 0 | O24: SubGroup4 | P24: =P15*100/$V$15 -> 3.0821918 | Q24: =Q15*100/$V$15 -> 29.794521 | R24: =R15*100/$V$15 -> 28.424658 | S24: =S15*100/$V$15 -> 24.657534 | T24: =T15*100/$V$15 -> 11.986301 | U24: =U15*100/$V$15 -> 2.0547945
O25: SubGroup5 | P25: =P16*100/$V$16 -> 1.056338 | Q25: =Q16*100/$V$16 -> 13.732394 | R25: =R16*100/$V$16 -> 19.014085 | S25: =S16*100/$V$16 -> 29.577465 | T25: =T16*100/$V$16 -> 25.352113 | U25: =U16*100/$V$16 -> 11.267606 | Y25: =292/2 -> 146
O26: SubGroup6 | P26: =P17*100/$V$17 -> 0 | Q26: =Q17*100/$V$17 -> 11.111111 | R26: =R17*100/$V$17 -> 18.888889 | S26: =S17*100/$V$17 -> 31.111111 | T26: =T17*100/$V$17 -> 26.666667 | U26: =U17*100/$V$17 -> 12.222222 | Y26: =V20/2 -> 184
O27: SubGroup7 | P27: =P18*100/$V$18 -> 3.5014006 | Q27: =Q18*100/$V$18 -> 26.785714 | R27: =R18*100/$V$18 -> 26.960784 | S27: =S18*100/$V$18 -> 23.879552 | T27: =T18*100/$V$18 -> 16.001401 | U27: =U18*100/$V$18 -> 2.8711485
O28: SubGroup8 | P28: =P19*100/$V$19 -> 0.52356021 | Q28: =Q19*100/$V$19 -> 8.6387435 | R28: =R19*100/$V$19 -> 15.706806 | S28: =S19*100/$V$19 -> 34.554974 | T28: =T19*100/$V$19 -> 30.366492 | U28: =U19*100/$V$19 -> 10.209424
O29: SubGroup9 | P29: =P20*100/$V$20 -> 4.076087 | Q29: =Q20*100/$V$20 -> 28.26087 | R29: =R20*100/$V$20 -> 29.619565 | S29: =S20*100/$V$20 -> 22.826087 | T29: =T20*100/$V$20 -> 13.315217 | U29: =U20*100/$V$20 -> 1.9021739
F32: =95*100/6800 -> 1.3970588
O33: ok | P33: =ROUND(P12/2,0) -> 12 | Q33: =ROUNDDOWN(Q12/2,0) -> 193 | R33: =ROUND(R12/2,0) -> 349 | S33: =ROUNDDOWN(S12/2,0) -> 552 | T33: =ROUND(T12/2,0) -> 550 | U33: =ROUNDDOWN(U12/2,0) -> 265 | V33: =SUM(P33:U33) -> 1921
O34: Deprived: me | P34: =ROUND(P13/2,0) -> 41 | Q34: =ROUNDDOWN(Q13/2,0) -> 274 | R34: =ROUND(R13/2,0) -> 266 | S34: =ROUNDDOWN(S13/2,0) -> 285 | T34: =ROUND(T13/2,0) -> 148 | U34: =ROUNDDOWN(U13/2,0) -> 28 | V34: =SUM(P34:U34) -> 1042
O35: Deprived: both partners | P35: =ROUND(P14/2,0) -> 112 | Q35: =ROUNDDOWN(Q14/2,0) -> 735 | R35: =ROUND(R14/2,0) -> 478 | S35: =ROUNDDOWN(S14/2,0) -> 288 | T35: =ROUND(T14/2,0) -> 88 | U35: =ROUNDDOWN(U14/2,0) -> 0 | V35: =SUM(P35:U35) -> 1701
O36: mixed me | P36: =ROUND(P15/2,0) -> 5 | Q36: =ROUNDDOWN(Q15/2,0) -> 43 | R36: =ROUNDDOWN(R15/2,0) -> 41 | S36: =ROUNDDOWN(S15/2,0) -> 36 | T36: =ROUND(T15/2,0) -> 18 | U36: =ROUNDDOWN(U15/2,0) -> 3 | V36: =SUM(P36:U36) -> 146
O37: Saturated: me | P37: =ROUND(P16/2,0) -> 2 | Q37: =ROUNDDOWN(Q16/2,0) -> 19 | R37: =ROUND(R16/2,0) -> 27 | S37: =ROUNDDOWN(S16/2,0) -> 42 | T37: =ROUND(T16/2,0) -> 36 | U37: =ROUNDDOWN(U16/2,0) -> 16 | V37: =SUM(P37:U37) -> 142
O38: Saturated: both partners | P38: =ROUND(P17/2,0) -> 0 | Q38: =ROUNDDOWN(Q17/2,0) -> 5 | R38: =ROUND(R17/2,0) -> 9 | S38: =ROUNDDOWN(S17/2,0) -> 14 | T38: =ROUND(T17/2,0) -> 12 | U38: =ROUNDDOWN(U17/2,0) -> 5 | V38: =SUM(P38:U38) -> 45
O39: Deprived: partner | P39: =ROUND(P18/2,0) -> 50 | Q39: =ROUNDDOWN(Q18/2,0) -> 382 | R39: =ROUND(R18/2,0) -> 385 | S39: =ROUNDDOWN(S18/2,0) -> 341 | T39: =ROUND(T18/2,0) -> 229 | U39: =ROUNDDOWN(U18/2,0) -> 41 | V39: =SUM(P39:U39) -> 1428
O40: Saturated: partner | P40: =ROUND(P19/2,0) -> 1 | Q40: =ROUND(Q19/2,0) -> 17 | R40: =ROUND(R19/2,0) -> 30 | S40: =ROUNDDOWN(S19/2,0) -> 66 | T40: =ROUND(T19/2,0) -> 58 | U40: =ROUNDDOWN(U19/2,0) -> 19 | V40: =SUM(P40:U40) -> 191
O41: mixed partner | P41: =ROUND(P20/2,0) -> 8 | Q41: =ROUNDDOWN(Q20/2,0) -> 52 | R41: =ROUND(R20/2,0) -> 55 | S41: =ROUNDDOWN(S20/2,0) -> 42 | T41: =ROUNDDOWN(T20/2,0) -> 24 | U41: =ROUNDDOWN(U20/2,0) -> 3 | V41: =SUM(P41:U41) -> 184
O42: ok | P42: =P33*100/$V$33 -> 0.62467465 | Q42: =Q33*100/$V$33 -> 10.046851 | R42: =R33*100/$V$33 -> 18.167621 | S42: =S33*100/$V$33 -> 28.735034 | T42: =T33*100/$V$33 -> 28.630921 | U42: =U33*100/$V$33 -> 13.794898
O43: Deprived: me | P43: =P34*100/$V$34 -> 3.9347409 | Q43: =Q34*100/$V$34 -> 26.295585 | R43: =R34*100/$V$34 -> 25.527831 | S43: =S34*100/$V$34 -> 27.351248 | T43: =T34*100/$V$34 -> 14.203455 | U43: =U34*100/$V$34 -> 2.6871401
O44: Deprived: both partners | P44: =P35*100/$V$35 -> 6.5843621 | Q44: =Q35*100/$V$35 -> 43.209877 | R44: =R35*100/$V$35 -> 28.101117 | S44: =S35*100/$V$35 -> 16.931217 | T44: =T35*100/$V$35 -> 5.1734274 | U44: =U35*100/$V$35 -> 0
O45: mixed me | P45: =P36*100/$V$36 -> 3.4246575 | Q45: =Q36*100/$V$36 -> 29.452055 | R45: =R36*100/$V$36 -> 28.082192 | S45: =S36*100/$V$36 -> 24.657534 | T45: =T36*100/$V$36 -> 12.328767 | U45: =U36*100/$V$36 -> 2.0547945
O46: Saturated: me | P46: =P37*100/$V$37 -> 1.4084507 | Q46: =Q37*100/$V$37 -> 13.380282 | R46: =R37*100/$V$37 -> 19.014085 | S46: =S37*100/$V$37 -> 29.577465 | T46: =T37*100/$V$37 -> 25.352113 | U46: =U37*100/$V$37 -> 11.267606
O47: Saturated: both partners | P47: =P38*100/$V$38 -> 0 | Q47: =Q38*100/$V$38 -> 11.111111 | R47: =R38*100/$V$38 -> 20 | S47: =S38*100/$V$38 -> 31.111111 | T47: =T38*100/$V$38 -> 26.666667 | U47: =U38*100/$V$38 -> 11.111111
O48: Deprived: partner | P48: =P39*100/$V$39 -> 3.5014006 | Q48: =Q39*100/$V$39 -> 26.7507 | R48: =R39*100/$V$39 -> 26.960784 | S48: =S39*100/$V$39 -> 23.879552 | T48: =T39*100/$V$39 -> 16.036415 | U48: =U39*100/$V$39 -> 2.8711485
O49: Saturated: partner | P49: =P40*100/$V$40 -> 0.52356021 | Q49: =Q40*100/$V$40 -> 8.9005236 | R49: =R40*100/$V$40 -> 15.706806 | S49: =S40*100/$V$40 -> 34.554974 | T49: =T40*100/$V$40 -> 30.366492 | U49: =U40*100/$V$40 -> 9.947644
O50: mixed partner | P50: =P41*100/$V$41 -> 4.3478261 | Q50: =Q41*100/$V$41 -> 28.26087 | R50: =R41*100/$V$41 -> 29.891304 | S50: =S41*100/$V$41 -> 22.826087 | T50: =T41*100/$V$41 -> 13.043478 | U50: =U41*100/$V$41 -> 1.6304348

Sheet Sheet3
D4: range | E4: mean | F4: sd | K4: 0 | L4: 205
B5: Age | C5: Dyad | D5: 18-79 | E5: 36.67831 | F5: 8.53506 | K5: 1 | L5: 79
C6: Women | D6: 18-65 | E6: 35.56032 | F6: 8.1116 | K6: 2 | L6: 147
C7: Men | D7: 18-79 | E7: 37.81603 | F7: 8.79435 | K7: 3 | L7: 3092
C8: Age difference | D8: ± 10 years | E8: 0.08426 | F8: 1.55317 | K8: 4 | L8: 1863
D9: nr | E9: % | K9: 6 | L9: 4195
B10: Education ISCED-11 | C10: Less than primary education | D10: 205 | E10: 1.5073529 | K10: 7 | L10: 2498 | N10: ISCED 0: Early childhood education (‘less than primary’ for educational attainment)
C11: Primary education | D11: 79 | E11: 0.58088235 | K11: 8 | L11: 518 | N11: ISCED 1: Primary education
C12: secondary education | D12: 5102 | E12: 37.514706 | N12: ISCED 2: Lower secondary education
C13: Bachelor | D13: 4195 | E13: 30.845588 | N13: ISCED 3: Upper secondary education
C14: Master | D14: 2498 | E14: 18.367647 | N14: ISCED 4: Post-secondary non-tertiary education
C15: Doctor | D15: 518 | E15: 3.8088235 | N15: ISCED 5: Short-cycle tertiary education
B16: Sex | C16: Female | D16: 6805 | E16: 50.036765 | N16: ISCED 6: Bachelor’s or equivalent level
C17: Male | D17: 6773 | E17: 49.801471 | N17: ISCED 7: Master’s or equivalent level
C18: Other | D18: 22 | E18: 0.16176471 | N18: ISCED 8: Doctoral or equivalent level
B19: Sexual orientation | C19: Homesexual | D19: 13142 | E19: 96.632353
C20: Heterosexual | D20: 458 | E20: 3.3676471
L22: Less than primary education | M22: =L4 -> 205 | N22: =M22*100/$N$29 -> 1.5073529
L23: Primary education | M23: =SUM(L5) -> 79 | N23: =M23*100/$N$29 -> 0.58088235
L24: secondary education | M24: =SUM(L6:L8) -> 5102 | N24: =M24*100/$N$29 -> 37.514706
L25: Bachelor | M25: =L9 -> 4195 | N25: =M25*100/$N$29 -> 30.845588
L26: Master | M26: =L10 -> 2498 | N26: =M26*100/$N$29 -> 18.367647
L27: Doctor | M27: =L11 -> 518 | N27: =M27*100/$N$29 -> 3.8088235
N29: 13600
L32: 6805 | M32: =L32*100/$N$29 -> 50.036765
D33: Depressiveness | E33: Loneliness | F33: Self-esteem | G33: Life Satisfaction | H33: Health | L33: 6773 | M33: =L33*100/$N$29 -> 49.801471
B34: Satisfied | C34: SubGroup1 | D34: 4.82 | E34: 1.61 | F34: 11.93 | G34: 8.2 | H34: 3.91 | L34: 22 | M34: =L34*100/$N$29 -> 0.16176471
B35: Deprived: me | C35: SubGroup2 | D35: 5.06 | E35: 1.87 | F35: 11.44 | G35: 7.89 | H35: 3.79
B36: Deprived: both | C36: SubGroup3 | D36: 5.25 | E36: 2.06 | F36: 11.1 | G36: 7.6 | H36: 3.68
B37: Mixed: me deprived, partner saturated | C37: SubGroup4 | D37: 5.41 | E37: 2.11 | F37: 11.19 | G37: 7.62 | H37: 3.66 | K37: het | L37: 13142 | M37: =L37*100/$N$29 -> 96.632353
B38: Saturated: me | C38: SubGroup5 | D38: 5.2 | E38: 1.82 | F38: 11.31 | G38: 7.82 | H38: 3.81 | K38: hom | L38: 458 | M38: =L38*100/$N$29 -> 3.3676471
B39: Saturated: both | C39: SubGroup6 | D39: 4.86 | E39: 1.72 | F39: 11.56 | G39: 8.18 | H39: 3.71
B40: Deprived: partner | C40: SubGroup7 | D40: 5.06 | E40: 1.83 | F40: 11.44 | G40: 7.83 | H40: 3.75 | N40: 'Deprived: Partner', 'Deprived: Me', 'Deprived: Both',
B41: Saturated: partner | C41: SubGroup8 | D41: 5.1 | E41: 1.79 | F41: 11.47 | G41: 7.96 | H41: 3.88 | N41: 'Saturated: Partner', 'Saturated: Me', 'Saturated: Both',
B42: Mixed: me saturated, partner deprived | C42: SubGroup9 | D42: 5.48 | E42: 2.23 | F42: 10.8 | G42: 7.38 | H42: 3.64 | N42: 'Mixed: Me deprived,partner saturated', 'Mixed: Me saturated,partner deprived',
C46: Subgroups division
B47: SubGroup1 | C47: Satisfied
B48: SubGroup2 | C48: Deprived: me
C49: Deprived: partner
B50: SubGroup3 | C50: Deprived: both
...

Sheet Sheet5
E5: Extraversion | F5: Openness | G5: Agreeableness | H5: Conscientiousness | I5: Neuroticism | L5: Depressiveness | M5: Loneliness | N5: Self-esteem | O5: Life Satisfaction | P5: Health | S5: Communication Quality | T5: Relationship Satisfaction | U5: Conflict Management
D6: SubGroup1 | E6: 9,42 | F6: 10,10 | G6: 11,10 | H6: 11,06 | I6: 7,62 | K6: SubGroup1 | L6: 4.82 | M6: 1.61 | N6: 11.93 | O6: 8.2 | P6: 3.91 | R6: SubGroup1 | S6: 23.44 | T6: 9.31 | U6: 24.35
D7: SubGroup2 | E7: 9,33 | F7: 9,97 | G7: 11,00 | H7: 11,02 | I7: 7,96 | K7: SubGroup2 | L7: 5.06 | M7: 1.87 | N7: 11.44 | O7: 7.89 | P7: 3.79 | R7: SubGroup2 | S7: 21.94 | T7: 8.65 | U7: 23.35
D8: SubGroup3 | E8: 9,21 | F8: 9,74 | G8: 10,77 | H8: 10,93 | I8: 8,28 | K8: SubGroup3 | L8: 5.25 | M8: 2.06 | N8: 11.1 | O8: 7.6 | P8: 3.68 | R8: SubGroup3 | S8: 20.72 | T8: 8.15 | U8: 22.71
D9: SubGroup4 | E9: 9,29 | F9: 10,04 | G9: 10,69 | H9: 10,82 | I9: 8,24 | K9: SubGroup4 | L9: 5.41 | M9: 2.11 | N9: 11.19 | O9: 7.62 | P9: 3.66 | R9: SubGroup4 | S9: 21.24 | T9: 8.26 | U9: 22.87
D10: SubGroup5 | E10: 9,38 | F10: 10,04 | G10: 11,00 | H10: 11,07 | I10: 8,07 | K10: SubGroup5 | L10: 5.2 | M10: 1.82 | N10: 11.31 | O10: 7.82 | P10: 3.81 | R10: SubGroup5 | S10: 22.77 | T10: 8.87 | U10: 23.56
D11: SubGroup6 | E11: 10,06 | F11: 9,54 | G11: 10,52 | H11: 11,57 | I11: 7,79 | K11: SubGroup6 | L11: 4.86 | M11: 1.72 | N11: 11.56 | O11: 8.18 | P11: 3.71 | R11: SubGroup6 | S11: 22.95 | T11: 8.9 | U11: 23.86
D12: SubGroup7 | E12: 9,28 | F12: 9,90 | G12: 10,95 | H12: 10,94 | I12: 8,01 | K12: SubGroup7 | L12: 5.06 | M12: 1.83 | N12: 11.44 | O12: 7.83 | P12: 3.75 | R12: SubGroup7 | S12: 21.83 | T12: 8.69 | U12: 23.44
D13: SubGroup8 | E13: 9,51 | F13: 10,05 | G13: 11,09 | H13: 10,98 | I13: 7,95 | K13: SubGroup8 | L13: 5.1 | M13: 1.79 | N13: 11.47 | O13: 7.96 | P13: 3.88 | R13: SubGroup8 | S13: 22.92 | T13: 9.01 | U13: 23.69
D14: SubGroup9 | E14: 9,23 | F14: 9,80 | G14: 10,89 | H14: 10,90 | I14: 8,43 | K14: SubGroup9 | L14: 5.48 | M14: 2.23 | N14: 10.8 | O14: 7.38 | P14: 3.64 | R14: SubGroup9 | S14: 21.12 | T14: 7.93 | U14: 22.61
E16: Extraversion | F16: Openness | G16: Agreeableness | H16: Conscientiousness | I16: Neuroticism | L16: Depressiveness | M16: Loneliness | N16: Self-esteem | O16: Life Satisfaction | P16: Health | S16: Communication Quality | T16: Relationship Satisfaction | U16: Conflict Management
A17: Satisfied | B17: SubGroup1 | D17: Satisfied | E17: 9,42 | F17: 10,10 | G17: 11,10 | H17: 11,06 | I17: 7,62 | K17: Satisfied | L17: 4.82 | M17: 1.61 | N17: 11.93 | O17: 8.2 | P17: 3.91 | R17: Satisfied | S17: 23.44 | T17: 9.31 | U17: 24.35
A18: Deprived: me | B18: SubGroup2 | D18: Deprived: me | E18: 9,33 | F18: 9,97 | G18: 11,00 | H18: 11,02 | I18: 7,96 | K18: Deprived: me | L18: 5.06 | M18: 1.87 | N18: 11.44 | O18: 7.89 | P18: 3.79 | R18: Deprived: me | S18: 21.94 | T18: 8.65 | U18: 23.35
A19: Deprived: both | B19: SubGroup3 | D19: Deprived: partner | E19: 9,28 | F19: 9,90 | G19: 10,95 | H19: 10,94 | I19: 8,01 | K19: Deprived: partner | L19: 5.06 | M19: 1.83 | N19: 11.44 | O19: 7.83 | P19: 3.75 | R19: Deprived: partner | S19: 21.83 | T19: 8.69 | U19: 23.44
A20: Mixed: me deprived, partner saturated | B20: SubGroup4 | D20: Deprived: both | E20: 9,21 | F20: 9,74 | G20: 10,77 | H20: 10,93 | I20: 8,28 | K20: Deprived: both | L20: 5.25 | M20: 2.06 | N20: 11.1 | O20: 7.6 | P20: 3.68 | R20: Deprived: both | S20: 20.72 | T20: 8.15 | U20: 22.71
A21: Saturated: me | B21: SubGroup5 | D21: Saturated: me | E21: 9,38 | F21: 10,04 | G21: 11,00 | H21: 11,07 | I21: 8,07 | K21: Saturated: me | L21: 5.2 | M21: 1.82 | N21: 11.31 | O21: 7.82 | P21: 3.81 | R21: Saturated: me | S21: 22.77 | T21: 8.87 | U21: 23.56
A22: Saturated: both | B22: SubGroup6 | D22: Saturated: partner | E22: 9,51 | F22: 10,05 | G22: 11,09 | H22: 10,98 | I22: 7,95 | K22: Saturated: partner | L22: 5.1 | M22: 1.79 | N22: 11.47 | O22: 7.96 | P22: 3.88 | R22: Saturated: partner | S22: 22.92 | T22: 9.01 | U22: 23.69
A23: Deprived: partner | B23: SubGroup7 | D23: Saturated: both | E23: 10,06 | F23: 9,54 | G23: 10,52 | H23: 11,57 | I23: 7,79 | K23: Saturated: both | L23: 4.86 | M23: 1.72 | N23: 11.56 | O23: 8.18 | P23: 3.71 | R23: Saturated: both | S23: 22.95 | T23: 8.9 | U23: 23.86
A24: Saturated: partner | B24: SubGroup8 | D24: Mixed: me deprived, partner saturated | E24: 9,29 | F24: 10,04 | G24: 10,69 | H24: 10,82 | I24: 8,24 | K24: Mixed: me deprived, partner saturated | L24: 5.41 | M24: 2.11 | N24: 11.19 | O24: 7.62 | P24: 3.66 | R24: Mixed: me deprived, partner saturated | S24: 21.24 | T24: 8.26 | U24: 22.87
A25: Mixed: me saturated, partner deprived | B25: SubGroup9 | D25: Mixed: me saturated, partner deprived | E25: 9,23 | F25: 9,80 | G25: 10,89 | H25: 10,90 | I25: 8,43 | K25: Mixed: me saturated, partner deprived | L25: 5.48 | M25: 2.23 | N25: 10.8 | O25: 7.38 | P25: 3.64 | R25: Mixed: me saturated, partner deprived | S25: 21.12 | T25: 7.93 | U25: 22.61
A27: Satisfied | B27: SubGroup1
A28: Deprived: me | B28: SubGroup2
A29: Deprived: partner | B29: SubGroup7
A30: Deprived: both | B30: SubGroup3
A31: Saturated: me | B31: SubGroup5
A32: Saturated: partner | B32: SubGroup8
A33: Saturated: both | B33: SubGroup6
A34: Mixed: me deprived, partner saturated | B34: SubGroup4
A35: Mixed: me saturated, partner deprived | B35: SubGroup9

Sheet Sheet4
C4: Not at all | D4: 1 to 5 times | E4: 6 to 10 times | F4: 11 to 20 times | G4: 21 to 50 times | H4: More than 50 times | L4: Subgroups division
C5: 95 | D5: 1768 | E5: 1945 (28.6%) | F5: 1876 (27.59%) | G5: 1007 | H5: 109 | L5: Satisfied
B6: -6800 | C6: -0.014 | D6: -0.26 | G6: -0.1481 | H6: -0.016 | L6: Deprived: me
C7: 6 | D7: 167 | E7: 382 | F7: 676 (35.19%) | G7: 589 | H7: 101 | L7: Deprived: partner
B8: n = 1921 (28.3%) | C8: -0.0031 | D8: -0.0869 | E8: -0.1989 | G8: -0.3066 | H8: -0.0526 | L8: Deprived: both
B9: Deprived: both partners | C9: 46 | D9: 840 | E9: 536 | F9: 242 (14.23%) | G9: 37 | H9: 0 | L9: Saturated: me
B10: n = 1701 (25.0%) | C10: -0.027 | D10: -0.4938 | E10: -0.3151 | G10: -0.0218 | H10: 0 | L10: Saturated: partner
B11: Deprived: one partner | C11: 35 | D11: 640 | E11: 825 | F11: 731 | G11: 239 (9.68%) | H11: 0 | L11: Saturated: both
B12: n = 2470 (36.3%) | C12: -0.0142 | D12: -0.2591 | E12: -0.334 | F12: -0.296 | H12: 0 | L12: Mixed: me deprived, partner saturated
B13: Deprived: me (n = 1042) | C13: 41 (3.93%) | D13: 274 (26.3%) | E13: 266 (25.53%) | F13: 285 (27.35%) | G13: 148 (14.2%) | H13: 28 (2.69%) | L13: Mixed: me saturated, partner deprived
B14: Deprived: partner (n = 1428) | C14: 50 (3.5%) | D14: 382 (26.75%) | E14: 385 (26.96%) | F14: 341 (23.88%) | G14: 229 (16.04%) | H14: 41 (2.87%)
B15: Saturated: both partners | C15: 0 | D15: 3 | E15: 11 | F15: 15 | G15: 14 | H15: 2
B16: n = 45 (0.7%) | C16: 0 | D16: -0.0667 | E16: -0.2444 | F16: -0.3333 | G16: -0.3111 | H16: -0.0444
B17: Saturated: One Partner | C17: 2 | D17: 29 | E17: 59 | F17: 139 (41.74%) | G17: 98 | H17: 6
B18: n = 333 (3.9%) | C18: -0.006 | D18: -0.0871 | E18: -0.1772 | G18: -0.2943 | H18: -0.018
B19: Saturated: me (n = 142) | C19: 2 (1.41%) | D19: 19 (13.38%) | E19: 27 (19.01%) | F19: 42 (29.58%) | G19: 36 (25.35%) | H19: 16 (11.27%)
B20: Saturated: partner (n = 191) | C20: 1 (0.52%) | D20: 17 (8.9%) | E20: 30 (15.71%) | F20: 66 (34.55%) | G20: 58 (30.37%) | H20: 19 (9.95%)
B21: Mixed: one deprived, one saturated | C21: 6 | D21: 89 | E21: 132 | F21: 73 | G21: 30 | H21: 0
B22: n = 330 (4.9%) | C22: -0.0182 | D22: -0.2697 | E22: -0.4 | F22: -0.2212 | G22: -0.0909 | H22: 0
B23: Me deprived, partner saturated (n = 146) | C23: 5 (3.42%) | D23: 43 (29.45%) | E23: 41 (28.08%) | F23: 36 (24.66%) | G23: 18 (12.33%) | H23: 3 (2.05%)
B24: Me saturated, partner deprived (n = 184) | C24: 8 (4.35%) | D24: 52 (28.26%) | E24: 55 (29.89%) | F24: 42 (22.83%) | G24: 24 (13.04%) | H24: 3 (1.63%)
B25: I renamed the groups, I think this is more intuitive for the reader (and satisfied seems more correct than alligned, because they may report different frequencies )
B28: Whole Sample
B29: Satisfied
